Workbook

Sheet Ma journée
A1: ☀ MA JOURNÉE
A2: L'onglet à ouvrir chaque matin : tes relances, les prospects les plus chauds à appeler, les alertes et tes objectifs du jour. Tout est automatique.
A3: =HYPERLINK("#'Saisie'!A1","↩ Saisie") | E3: =HYPERLINK("#'Tableau de bord'!A1","📊 Tableau de bord")
B4: =TODAY() | E4: =IF(WEEKDAY(TODAY(),2)=1,"📅 Lundi : fais ta revue hebdo de 15 min (voir SOP)","")
B6: 🎯 OBJECTIFS DU JOUR
B7: Objectif | C7: Fait | D7: Cible | E7: % | F7: Progression | I7: Reste
B8: Nouveaux prospects | C8: =COUNTIFS('Prospects'!$B$5:$B$504,TODAY()) | D8: ='Paramètres'!$B$6 | E8: =IFERROR(C8/D8,0) | F8: =REPT("█",ROUND(MIN(1,E8)*20,0))&REPT("░",20-ROUND(MIN(1,E8)*20,0)) | I8: =MAX(0,D8-C8)
B9: Appels | C9: =COUNTIFS('Saisie'!$A$5:$A$2004,TODAY(),'Saisie'!$D$5:$D$2004,"Appel",'Saisie'!$AU$5:$AU$2004,1) | D9: ='Paramètres'!$B$7 | E9: =IFERROR(C9/D9,0) | F9: =REPT("█",ROUND(MIN(1,E9)*20,0))&REPT("░",20-ROUND(MIN(1,E9)*20,0)) | I9: =MAX(0,D9-C9)
B10: DM | C10: =COUNTIFS('Saisie'!$A$5:$A$2004,TODAY(),'Saisie'!$D$5:$D$2004,"DM",'Saisie'!$AU$5:$AU$2004,1) | D10: ='Paramètres'!$B$8 | E10: =IFERROR(C10/D10,0) | F10: =REPT("█",ROUND(MIN(1,E10)*20,0))&REPT("░",20-ROUND(MIN(1,E10)*20,0)) | I10: =MAX(0,D10-C10)
B12: 🔴 À RELANCER AUJOURD'HUI ET EN RETARD
B13: Entreprise | C13: Contact | D13: Téléphone | E13: WhatsApp | F13: Canal | G13: Étape | H13: Prochaine action | I13: Relance | J13: Heure | K13: Retard (j)
B14: =IFERROR(INDEX('Prospects'!$C$5:$C$504,MATCH(1,'Prospects'!$BU$5:$BU$504,0))&"","") | C14: =IFERROR(INDEX('Prospects'!$J$5:$J$504,MATCH(1,'Prospects'!$BU$5:$BU$504,0))&"","") | D14: =IFERROR(INDEX('Prospects'!$K$5:$K$504,MATCH(1,'Prospects'!$BU$5:$BU$504,0))&"","") | E14: =IF(D14="","",HYPERLINK("https://wa.me/"&IF(LEFT(SUBSTITUTE(D14," ",""),1)="0",'Paramètres'!$B$35&MID(SUBSTITUTE(D14," ",""),2,20),SUBSTITUTE(D14," ","")),"Ouvrir")) | F14: =IFERROR(INDEX('Prospects'!$N$5:$N$504,MATCH(1,'Prospects'!$BU$5:$BU$504,0))&"","") | G14: =IFERROR(INDEX('Prospects'!$D$5:$D$504,MATCH(1,'Prospects'!$BU$5:$BU$504,0))&"","") | H14: =IFERROR(INDEX('Prospects'!$I$5:$I$504,MATCH(1,'Prospects'!$BU$5:$BU$504,0))&"","") | I14: =IFERROR(IF(INDEX('Prospects'!$G$5:$G$504,MATCH(1,'Prospects'!$BU$5:$BU$504,0))="","",INDEX('Prospects'!$G$5:$G$504,MATCH(1,'Prospects'!$BU$5:$BU$504,0))),"") | J14: =IFERROR(IF(INDEX('Prospects'!$H$5:$H$504,MATCH(1,'Prospects'!$BU$5:$BU$504,0))="","",INDEX('Prospects'!$H$5:$H$504,MATCH(1,'Prospects'!$BU$5:$BU$504,0))),"") | K14: =IF(I14="","",TODAY()-I14)
B15: =IFERROR(INDEX('Prospects'!$C$5:$C$504,MATCH(2,'Prospects'!$BU$5:$BU$504,0))&"","") | C15: =IFERROR(INDEX('Prospects'!$J$5:$J$504,MATCH(2,'Prospects'!$BU$5:$BU$504,0))&"","") | D15: =IFERROR(INDEX('Prospects'!$K$5:$K$504,MATCH(2,'Prospects'!$BU$5:$BU$504,0))&"","") | E15: =IF(D15="","",HYPERLINK("https://wa.me/"&IF(LEFT(SUBSTITUTE(D15," ",""),1)="0",'Paramètres'!$B$35&MID(SUBSTITUTE(D15," ",""),2,20),SUBSTITUTE(D15," ","")),"Ouvrir")) | F15: =IFERROR(INDEX('Prospects'!$N$5:$N$504,MATCH(2,'Prospects'!$BU$5:$BU$504,0))&"","") | G15: =IFERROR(INDEX('Prospects'!$D$5:$D$504,MATCH(2,'Prospects'!$BU$5:$BU$504,0))&"","") | H15: =IFERROR(INDEX('Prospects'!$I$5:$I$504,MATCH(2,'Prospects'!$BU$5:$BU$504,0))&"","") | I15: =IFERROR(IF(INDEX('Prospects'!$G$5:$G$504,MATCH(2,'Prospects'!$BU$5:$BU$504,0))="","",INDEX('Prospects'!$G$5:$G$504,MATCH(2,'Prospects'!$BU$5:$BU$504,0))),"") | J15: =IFERROR(IF(INDEX('Prospects'!$H$5:$H$504,MATCH(2,'Prospects'!$BU$5:$BU$504,0))="","",INDEX('Prospects'!$H$5:$H$504,MATCH(2,'Prospects'!$BU$5:$BU$504,0))),"") | K15: =IF(I15="","",TODAY()-I15)
B16: =IFERROR(INDEX('Prospects'!$C$5:$C$504,MATCH(3,'Prospects'!$BU$5:$BU$504,0))&"","") | C16: =IFERROR(INDEX('Prospects'!$J$5:$J$504,MATCH(3,'Prospects'!$BU$5:$BU$504,0))&"","") | D16: =IFERROR(INDEX('Prospects'!$K$5:$K$504,MATCH(3,'Prospects'!$BU$5:$BU$504,0))&"","") | E16: =IF(D16="","",HYPERLINK("https://wa.me/"&IF(LEFT(SUBSTITUTE(D16," ",""),1)="0",'Paramètres'!$B$35&MID(SUBSTITUTE(D16," ",""),2,20),SUBSTITUTE(D16," ","")),"Ouvrir")) | F16: =IFERROR(INDEX('Prospects'!$N$5:$N$504,MATCH(3,'Prospects'!$BU$5:$BU$504,0))&"","") | G16: =IFERROR(INDEX('Prospects'!$D$5:$D$504,MATCH(3,'Prospects'!$BU$5:$BU$504,0))&"","") | H16: =IFERROR(INDEX('Prospects'!$I$5:$I$504,MATCH(3,'Prospects'!$BU$5:$BU$504,0))&"","") | I16: =IFERROR(IF(INDEX('Prospects'!$G$5:$G$504,MATCH(3,'Prospects'!$BU$5:$BU$504,0))="","",INDEX('Prospects'!$G$5:$G$504,MATCH(3,'Prospects'!$BU$5:$BU$504,0))),"") | J16: =IFERROR(IF(INDEX('Prospects'!$H$5:$H$504,MATCH(3,'Prospects'!$BU$5:$BU$504,0))="","",INDEX('Prospects'!$H$5:$H$504,MATCH(3,'Prospects'!$BU$5:$BU$504,0))),"") | K16: =IF(I16="","",TODAY()-I16)
B17: =IFERROR(INDEX('Prospects'!$C$5:$C$504,MATCH(4,'Prospects'!$BU$5:$BU$504,0))&"","") | C17: =IFERROR(INDEX('Prospects'!$J$5:$J$504,MATCH(4,'Prospects'!$BU$5:$BU$504,0))&"","") | D17: =IFERROR(INDEX('Prospects'!$K$5:$K$504,MATCH(4,'Prospects'!$BU$5:$BU$504,0))&"","") | E17: =IF(D17="","",HYPERLINK("https://wa.me/"&IF(LEFT(SUBSTITUTE(D17," ",""),1)="0",'Paramètres'!$B$35&MID(SUBSTITUTE(D17," ",""),2,20),SUBSTITUTE(D17," ","")),"Ouvrir")) | F17: =IFERROR(INDEX('Prospects'!$N$5:$N$504,MATCH(4,'Prospects'!$BU$5:$BU$504,0))&"","") | G17: =IFERROR(INDEX('Prospects'!$D$5:$D$504,MATCH(4,'Prospects'!$BU$5:$BU$504,0))&"","") | H17: =IFERROR(INDEX('Prospects'!$I$5:$I$504,MATCH(4,'Prospects'!$BU$5:$BU$504,0))&"","") | I17: =IFERROR(IF(INDEX('Prospects'!$G$5:$G$504,MATCH(4,'Prospects'!$BU$5:$BU$504,0))="","",INDEX('Prospects'!$G$5:$G$504,MATCH(4,'Prospects'!$BU$5:$BU$504,0))),"") | J17: =IFERROR(IF(INDEX('Prospects'!$H$5:$H$504,MATCH(4,'Prospects'!$BU$5:$BU$504,0))="","",INDEX('Prospects'!$H$5:$H$504,MATCH(4,'Prospects'!$BU$5:$BU$504,0))),"") | K17: =IF(I17="","",TODAY()-I17)
B18: =IFERROR(INDEX('Prospects'!$C$5:$C$504,MATCH(5,'Prospects'!$BU$5:$BU$504,0))&"","") | C18: =IFERROR(INDEX('Prospects'!$J$5:$J$504,MATCH(5,'Prospects'!$BU$5:$BU$504,0))&"","") | D18: =IFERROR(INDEX('Prospects'!$K$5:$K$504,MATCH(5,'Prospects'!$BU$5:$BU$504,0))&"","") | E18: =IF(D18="","",HYPERLINK("https://wa.me/"&IF(LEFT(SUBSTITUTE(D18," ",""),1)="0",'Paramètres'!$B$35&MID(SUBSTITUTE(D18," ",""),2,20),SUBSTITUTE(D18," ","")),"Ouvrir")) | F18: =IFERROR(INDEX('Prospects'!$N$5:$N$504,MATCH(5,'Prospects'!$BU$5:$BU$504,0))&"","") | G18: =IFERROR(INDEX('Prospects'!$D$5:$D$504,MATCH(5,'Prospects'!$BU$5:$BU$504,0))&"","") | H18: =IFERROR(INDEX('Prospects'!$I$5:$I$504,MATCH(5,'Prospects'!$BU$5:$BU$504,0))&"","") | I18: =IFERROR(IF(INDEX('Prospects'!$G$5:$G$504,MATCH(5,'Prospects'!$BU$5:$BU$504,0))="","",INDEX('Prospects'!$G$5:$G$504,MATCH(5,'Prospects'!$BU$5:$BU$504,0))),"") | J18: =IFERROR(IF(INDEX('Prospects'!$H$5:$H$504,MATCH(5,'Prospects'!$BU$5:$BU$504,0))="","",INDEX('Prospects'!$H$5:$H$504,MATCH(5,'Prospects'!$BU$5:$BU$504,0))),"") | K18: =IF(I18="","",TODAY()-I18)
B19: =IFERROR(INDEX('Prospects'!$C$5:$C$504,MATCH(6,'Prospects'!$BU$5:$BU$504,0))&"","") | C19: =IFERROR(INDEX('Prospects'!$J$5:$J$504,MATCH(6,'Prospects'!$BU$5:$BU$504,0))&"","") | D19: =IFERROR(INDEX('Prospects'!$K$5:$K$504,MATCH(6,'Prospects'!$BU$5:$BU$504,0))&"","") | E19: =IF(D19="","",HYPERLINK("https://wa.me/"&IF(LEFT(SUBSTITUTE(D19," ",""),1)="0",'Paramètres'!$B$35&MID(SUBSTITUTE(D19," ",""),2,20),SUBSTITUTE(D19," ","")),"Ouvrir")) | F19: =IFERROR(INDEX('Prospects'!$N$5:$N$504,MATCH(6,'Prospects'!$BU$5:$BU$504,0))&"","") | G19: =IFERROR(INDEX('Prospects'!$D$5:$D$504,MATCH(6,'Prospects'!$BU$5:$BU$504,0))&"","") | H19: =IFERROR(INDEX('Prospects'!$I$5:$I$504,MATCH(6,'Prospects'!$BU$5:$BU$504,0))&"","") | I19: =IFERROR(IF(INDEX('Prospects'!$G$5:$G$504,MATCH(6,'Prospects'!$BU$5:$BU$504,0))="","",INDEX('Prospects'!$G$5:$G$504,MATCH(6,'Prospects'!$BU$5:$BU$504,0))),"") | J19: =IFERROR(IF(INDEX('Prospects'!$H$5:$H$504,MATCH(6,'Prospects'!$BU$5:$BU$504,0))="","",INDEX('Prospects'!$H$5:$H$504,MATCH(6,'Prospects'!$BU$5:$BU$504,0))),"") | K19: =IF(I19="","",TODAY()-I19)
B20: =IFERROR(INDEX('Prospects'!$C$5:$C$504,MATCH(7,'Prospects'!$BU$5:$BU$504,0))&"","") | C20: =IFERROR(INDEX('Prospects'!$J$5:$J$504,MATCH(7,'Prospects'!$BU$5:$BU$504,0))&"","") | D20: =IFERROR(INDEX('Prospects'!$K$5:$K$504,MATCH(7,'Prospects'!$BU$5:$BU$504,0))&"","") | E20: =IF(D20="","",HYPERLINK("https://wa.me/"&IF(LEFT(SUBSTITUTE(D20," ",""),1)="0",'Paramètres'!$B$35&MID(SUBSTITUTE(D20," ",""),2,20),SUBSTITUTE(D20," ","")),"Ouvrir")) | F20: =IFERROR(INDEX('Prospects'!$N$5:$N$504,MATCH(7,'Prospects'!$BU$5:$BU$504,0))&"","") | G20: =IFERROR(INDEX('Prospects'!$D$5:$D$504,MATCH(7,'Prospects'!$BU$5:$BU$504,0))&"","") | H20: =IFERROR(INDEX('Prospects'!$I$5:$I$504,MATCH(7,'Prospects'!$BU$5:$BU$504,0))&"","") | I20: =IFERROR(IF(INDEX('Prospects'!$G$5:$G$504,MATCH(7,'Prospects'!$BU$5:$BU$504,0))="","",INDEX('Prospects'!$G$5:$G$504,MATCH(7,'Prospects'!$BU$5:$BU$504,0))),"") | J20: =IFERROR(IF(INDEX('Prospects'!$H$5:$H$504,MATCH(7,'Prospects'!$BU$5:$BU$504,0))="","",INDEX('Prospects'!$H$5:$H$504,MATCH(7,'Prospects'!$BU$5:$BU$504,0))),"") | K20: =IF(I20="","",TODAY()-I20)
B21: =IFERROR(INDEX('Prospects'!$C$5:$C$504,MATCH(8,'Prospects'!$BU$5:$BU$504,0))&"","") | C21: =IFERROR(INDEX('Prospects'!$J$5:$J$504,MATCH(8,'Prospects'!$BU$5:$BU$504,0))&"","") | D21: =IFERROR(INDEX('Prospects'!$K$5:$K$504,MATCH(8,'Prospects'!$BU$5:$BU$504,0))&"","") | E21: =IF(D21="","",HYPERLINK("https://wa.me/"&IF(LEFT(SUBSTITUTE(D21," ",""),1)="0",'Paramètres'!$B$35&MID(SUBSTITUTE(D21," ",""),2,20),SUBSTITUTE(D21," ","")),"Ouvrir")) | F21: =IFERROR(INDEX('Prospects'!$N$5:$N$504,MATCH(8,'Prospects'!$BU$5:$BU$504,0))&"","") | G21: =IFERROR(INDEX('Prospects'!$D$5:$D$504,MATCH(8,'Prospects'!$BU$5:$BU$504,0))&"","") | H21: =IFERROR(INDEX('Prospects'!$I$5:$I$504,MATCH(8,'Prospects'!$BU$5:$BU$504,0))&"","") | I21: =IFERROR(IF(INDEX('Prospects'!$G$5:$G$504,MATCH(8,'Prospects'!$BU$5:$BU$504,0))="","",INDEX('Prospects'!$G$5:$G$504,MATCH(8,'Prospects'!$BU$5:$BU$504,0))),"") | J21: =IFERROR(IF(INDEX('Prospects'!$H$5:$H$504,MATCH(8,'Prospects'!$BU$5:$BU$504,0))="","",INDEX('Prospects'!$H$5:$H$504,MATCH(8,'Prospects'!$BU$5:$BU$504,0))),"") | K21: =IF(I21="","",TODAY()-I21)
B22: =IFERROR(INDEX('Prospects'!$C$5:$C$504,MATCH(9,'Prospects'!$BU$5:$BU$504,0))&"","") | C22: =IFERROR(INDEX('Prospects'!$J$5:$J$504,MATCH(9,'Prospects'!$BU$5:$BU$504,0))&"","") | D22: =IFERROR(INDEX('Prospects'!$K$5:$K$504,MATCH(9,'Prospects'!$BU$5:$BU$504,0))&"","") | E22: =IF(D22="","",HYPERLINK("https://wa.me/"&IF(LEFT(SUBSTITUTE(D22," ",""),1)="0",'Paramètres'!$B$35&MID(SUBSTITUTE(D22," ",""),2,20),SUBSTITUTE(D22," ","")),"Ouvrir")) | F22: =IFERROR(INDEX('Prospects'!$N$5:$N$504,MATCH(9,'Prospects'!$BU$5:$BU$504,0))&"","") | G22: =IFERROR(INDEX('Prospects'!$D$5:$D$504,MATCH(9,'Prospects'!$BU$5:$BU$504,0))&"","") | H22: =IFERROR(INDEX('Prospects'!$I$5:$I$504,MATCH(9,'Prospects'!$BU$5:$BU$504,0))&"","") | I22: =IFERROR(IF(INDEX('Prospects'!$G$5:$G$504,MATCH(9,'Prospects'!$BU$5:$BU$504,0))="","",INDEX('Prospects'!$G$5:$G$504,MATCH(9,'Prospects'!$BU$5:$BU$504,0))),"") | J22: =IFERROR(IF(INDEX('Prospects'!$H$5:$H$504,MATCH(9,'Prospects'!$BU$5:$BU$504,0))="","",INDEX('Prospects'!$H$5:$H$504,MATCH(9,'Prospects'!$BU$5:$BU$504,0))),"") | K22: =IF(I22="","",TODAY()-I22)
B23: =IFERROR(INDEX('Prospects'!$C$5:$C$504,MATCH(10,'Prospects'!$BU$5:$BU$504,0))&"","") | C23: =IFERROR(INDEX('Prospects'!$J$5:$J$504,MATCH(10,'Prospects'!$BU$5:$BU$504,0))&"","") | D23: =IFERROR(INDEX('Prospects'!$K$5:$K$504,MATCH(10,'Prospects'!$BU$5:$BU$504,0))&"","") | E23: =IF(D23="","",HYPERLINK("https://wa.me/"&IF(LEFT(SUBSTITUTE(D23," ",""),1)="0",'Paramètres'!$B$35&MID(SUBSTITUTE(D23," ",""),2,20),SUBSTITUTE(D23," ","")),"Ouvrir")) | F23: =IFERROR(INDEX('Prospects'!$N$5:$N$504,MATCH(10,'Prospects'!$BU$5:$BU$504,0))&"","") | G23: =IFERROR(INDEX('Prospects'!$D$5:$D$504,MATCH(10,'Prospects'!$BU$5:$BU$504,0))&"","") | H23: =IFERROR(INDEX('Prospects'!$I$5:$I$504,MATCH(10,'Prospects'!$BU$5:$BU$504,0))&"","") | I23: =IFERROR(IF(INDEX('Prospects'!$G$5:$G$504,MATCH(10,'Prospects'!$BU$5:$BU$504,0))="","",INDEX('Prospects'!$G$5:$G$504,MATCH(10,'Prospects'!$BU$5:$BU$504,0))),"") | J23: =IFERROR(IF(INDEX('Prospects'!$H$5:$H$504,MATCH(10,'Prospects'!$BU$5:$BU$504,0))="","",INDEX('Prospects'!$H$5:$H$504,MATCH(10,'Prospects'!$BU$5:$BU$504,0))),"") | K23: =IF(I23="","",TODAY()-I23)
B24: =IFERROR(INDEX('Prospects'!$C$5:$C$504,MATCH(11,'Prospects'!$BU$5:$BU$504,0))&"","") | C24: =IFERROR(INDEX('Prospects'!$J$5:$J$504,MATCH(11,'Prospects'!$BU$5:$BU$504,0))&"","") | D24: =IFERROR(INDEX('Prospects'!$K$5:$K$504,MATCH(11,'Prospects'!$BU$5:$BU$504,0))&"","") | E24: =IF(D24="","",HYPERLINK("https://wa.me/"&IF(LEFT(SUBSTITUTE(D24," ",""),1)="0",'Paramètres'!$B$35&MID(SUBSTITUTE(D24," ",""),2,20),SUBSTITUTE(D24," ","")),"Ouvrir")) | F24: =IFERROR(INDEX('Prospects'!$N$5:$N$504,MATCH(11,'Prospects'!$BU$5:$BU$504,0))&"","") | G24: =IFERROR(INDEX('Prospects'!$D$5:$D$504,MATCH(11,'Prospects'!$BU$5:$BU$504,0))&"","") | H24: =IFERROR(INDEX('Prospects'!$I$5:$I$504,MATCH(11,'Prospects'!$BU$5:$BU$504,0))&"","") | I24: =IFERROR(IF(INDEX('Prospects'!$G$5:$G$504,MATCH(11,'Prospects'!$BU$5:$BU$504,0))="","",INDEX('Prospects'!$G$5:$G$504,MATCH(11,'Prospects'!$BU$5:$BU$504,0))),"") | J24: =IFERROR(IF(INDEX('Prospects'!$H$5:$H$504,MATCH(11,'Prospects'!$BU$5:$BU$504,0))="","",INDEX('Prospects'!$H$5:$H$504,MATCH(11,'Prospects'!$BU$5:$BU$504,0))),"") | K24: =IF(I24="","",TODAY()-I24)
B25: =IFERROR(INDEX('Prospects'!$C$5:$C$504,MATCH(12,'Prospects'!$BU$5:$BU$504,0))&"","") | C25: =IFERROR(INDEX('Prospects'!$J$5:$J$504,MATCH(12,'Prospects'!$BU$5:$BU$504,0))&"","") | D25: =IFERROR(INDEX('Prospects'!$K$5:$K$504,MATCH(12,'Prospects'!$BU$5:$BU$504,0))&"","") | E25: =IF(D25="","",HYPERLINK("https://wa.me/"&IF(LEFT(SUBSTITUTE(D25," ",""),1)="0",'Paramètres'!$B$35&MID(SUBSTITUTE(D25," ",""),2,20),SUBSTITUTE(D25," ","")),"Ouvrir")) | F25: =IFERROR(INDEX('Prospects'!$N$5:$N$504,MATCH(12,'Prospects'!$BU$5:$BU$504,0))&"","") | G25: =IFERROR(INDEX('Prospects'!$D$5:$D$504,MATCH(12,'Prospects'!$BU$5:$BU$504,0))&"","") | H25: =IFERROR(INDEX('Prospects'!$I$5:$I$504,MATCH(12,'Prospects'!$BU$5:$BU$504,0))&"","") | I25: =IFERROR(IF(INDEX('Prospects'!$G$5:$G$504,MATCH(12,'Prospects'!$BU$5:$BU$504,0))="","",INDEX('Prospects'!$G$5:$G$504,MATCH(12,'Prospects'!$BU$5:$BU$504,0))),"") | J25: =IFERROR(IF(INDEX('Prospects'!$H$5:$H$504,MATCH(12,'Prospects'!$BU$5:$BU$504,0))="","",INDEX('Prospects'!$H$5:$H$504,MATCH(12,'Prospects'!$BU$5:$BU$504,0))),"") | K25: =IF(I25="","",TODAY()-I25)
B26: =IFERROR(INDEX('Prospects'!$C$5:$C$504,MATCH(13,'Prospects'!$BU$5:$BU$504,0))&"","") | C26: =IFERROR(INDEX('Prospects'!$J$5:$J$504,MATCH(13,'Prospects'!$BU$5:$BU$504,0))&"","") | D26: =IFERROR(INDEX('Prospects'!$K$5:$K$504,MATCH(13,'Prospects'!$BU$5:$BU$504,0))&"","") | E26: =IF(D26="","",HYPERLINK("https://wa.me/"&IF(LEFT(SUBSTITUTE(D26," ",""),1)="0",'Paramètres'!$B$35&MID(SUBSTITUTE(D26," ",""),2,20),SUBSTITUTE(D26," ","")),"Ouvrir")) | F26: =IFERROR(INDEX('Prospects'!$N$5:$N$504,MATCH(13,'Prospects'!$BU$5:$BU$504,0))&"","") | G26: =IFERROR(INDEX('Prospects'!$D$5:$D$504,MATCH(13,'Prospects'!$BU$5:$BU$504,0))&"","") | H26: =IFERROR(INDEX('Prospects'!$I$5:$I$504,MATCH(13,'Prospects'!$BU$5:$BU$504,0))&"","") | I26: =IFERROR(IF(INDEX('Prospects'!$G$5:$G$504,MATCH(13,'Prospects'!$BU$5:$BU$504,0))="","",INDEX('Prospects'!$G$5:$G$504,MATCH(13,'Prospects'!$BU$5:$BU$504,0))),"") | J26: =IFERROR(IF(INDEX('Prospects'!$H$5:$H$504,MATCH(13,'Prospects'!$BU$5:$BU$504,0))="","",INDEX('Prospects'!$H$5:$H$504,MATCH(13,'Prospects'!$BU$5:$BU$504,0))),"") | K26: =IF(I26="","",TODAY()-I26)
B27: =IFERROR(INDEX('Prospects'!$C$5:$C$504,MATCH(14,'Prospects'!$BU$5:$BU$504,0))&"","") | C27: =IFERROR(INDEX('Prospects'!$J$5:$J$504,MATCH(14,'Prospects'!$BU$5:$BU$504,0))&"","") | D27: =IFERROR(INDEX('Prospects'!$K$5:$K$504,MATCH(14,'Prospects'!$BU$5:$BU$504,0))&"","") | E27: =IF(D27="","",HYPERLINK("https://wa.me/"&IF(LEFT(SUBSTITUTE(D27," ",""),1)="0",'Paramètres'!$B$35&MID(SUBSTITUTE(D27," ",""),2,20),SUBSTITUTE(D27," ","")),"Ouvrir")) | F27: =IFERROR(INDEX('Prospects'!$N$5:$N$504,MATCH(14,'Prospects'!$BU$5:$BU$504,0))&"","") | G27: =IFERROR(INDEX('Prospects'!$D$5:$D$504,MATCH(14,'Prospects'!$BU$5:$BU$504,0))&"","") | H27: =IFERROR(INDEX('Prospects'!$I$5:$I$504,MATCH(14,'Prospects'!$BU$5:$BU$504,0))&"","") | I27: =IFERROR(IF(INDEX('Prospects'!$G$5:$G$504,MATCH(14,'Prospects'!$BU$5:$BU$504,0))="","",INDEX('Prospects'!$G$5:$G$504,MATCH(14,'Prospects'!$BU$5:$BU$504,0))),"") | J27: =IFERROR(IF(INDEX('Prospects'!$H$5:$H$504,MATCH(14,'Prospects'!$BU$5:$BU$504,0))="","",INDEX('Prospects'!$H$5:$H$504,MATCH(14,'Prospects'!$BU$5:$BU$504,0))),"") | K27: =IF(I27="","",TODAY()-I27)
B28: =IFERROR(INDEX('Prospects'!$C$5:$C$504,MATCH(15,'Prospects'!$BU$5:$BU$504,0))&"","") | C28: =IFERROR(INDEX('Prospects'!$J$5:$J$504,MATCH(15,'Prospects'!$BU$5:$BU$504,0))&"","") | D28: =IFERROR(INDEX('Prospects'!$K$5:$K$504,MATCH(15,'Prospects'!$BU$5:$BU$504,0))&"","") | E28: =IF(D28="","",HYPERLINK("https://wa.me/"&IF(LEFT(SUBSTITUTE(D28," ",""),1)="0",'Paramètres'!$B$35&MID(SUBSTITUTE(D28," ",""),2,20),SUBSTITUTE(D28," ","")),"Ouvrir")) | F28: =IFERROR(INDEX('Prospects'!$N$5:$N$504,MATCH(15,'Prospects'!$BU$5:$BU$504,0))&"","") | G28: =IFERROR(INDEX('Prospects'!$D$5:$D$504,MATCH(15,'Prospects'!$BU$5:$BU$504,0))&"","") | H28: =IFERROR(INDEX('Prospects'!$I$5:$I$504,MATCH(15,'Prospects'!$BU$5:$BU$504,0))&"","") | I28: =IFERROR(IF(INDEX('Prospects'!$G$5:$G$504,MATCH(15,'Prospects'!$BU$5:$BU$504,0))="","",INDEX('Prospects'!$G$5:$G$504,MATCH(15,'Prospects'!$BU$5:$BU$504,0))),"") | J28: =IFERROR(IF(INDEX('Prospects'!$H$5:$H$504,MATCH(15,'Prospects'!$BU$5:$BU$504,0))="","",INDEX('Prospects'!$H$5:$H$504,MATCH(15,'Prospects'!$BU$5:$BU$504,0))),"") | K28: =IF(I28="","",TODAY()-I28)
B29: =IF(MAX('Prospects'!$BU$5:$BU$504)>15,"+ "&(MAX('Prospects'!$BU$5:$BU$504)-15)&" autres relances : filtre la colonne Prochaine relance dans Prospects.","")
B31: 🔥 LES 10 PROSPECTS LES PLUS CHAUDS À APPELER
B32: Entreprise | C32: Contact | D32: Téléphone | E32: Instagram | F32: Score | G32: Étape | H32: Besoin / dernière action | I32: Tentatives | J32: Pub active | K32: Secteur
B33: =IFERROR(INDEX('Prospects'!$C$5:$C$504,MATCH(LARGE('Prospects'!$BT$5:$BT$504,1),'Prospects'!$BT$5:$BT$504,0)),"") | C33: =IFERROR(INDEX('Prospects'!$J$5:$J$504,MATCH(LARGE('Prospects'!$BT$5:$BT$504,1),'Prospects'!$BT$5:$BT$504,0)),"") | D33: =IFERROR(INDEX('Prospects'!$K$5:$K$504,MATCH(LARGE('Prospects'!$BT$5:$BT$504,1),'Prospects'!$BT$5:$BT$504,0)),"") | E33: =IFERROR(INDEX('Prospects'!$BC$5:$BC$504,MATCH(LARGE('Prospects'!$BT$5:$BT$504,1),'Prospects'!$BT$5:$BT$504,0)),"") | F33: =IFERROR(INDEX('Prospects'!$E$5:$E$504,MATCH(LARGE('Prospects'!$BT$5:$BT$504,1),'Prospects'!$BT$5:$BT$504,0)),"") | G33: =IFERROR(INDEX('Prospects'!$D$5:$D$504,MATCH(LARGE('Prospects'!$BT$5:$BT$504,1),'Prospects'!$BT$5:$BT$504,0)),"") | H33: =IFERROR(INDEX('Prospects'!$I$5:$I$504,MATCH(LARGE('Prospects'!$BT$5:$BT$504,1),'Prospects'!$BT$5:$BT$504,0)),"") | I33: =IFERROR(INDEX('Prospects'!$O$5:$O$504,MATCH(LARGE('Prospects'!$BT$5:$BT$504,1),'Prospects'!$BT$5:$BT$504,0)),"") | J33: =IFERROR(INDEX('Prospects'!$Z$5:$Z$504,MATCH(LARGE('Prospects'!$BT$5:$BT$504,1),'Prospects'!$BT$5:$BT$504,0)),"") | K33: =IFERROR(INDEX('Prospects'!$S$5:$S$504,MATCH(LARGE('Prospects'!$BT$5:$BT$504,1),'Prospects'!$BT$5:$BT$504,0)),"")
B34: =IFERROR(INDEX('Prospects'!$C$5:$C$504,MATCH(LARGE('Prospects'!$BT$5:$BT$504,2),'Prospects'!$BT$5:$BT$504,0)),"") | C34: =IFERROR(INDEX('Prospects'!$J$5:$J$504,MATCH(LARGE('Prospects'!$BT$5:$BT$504,2),'Prospects'!$BT$5:$BT$504,0)),"") | D34: =IFERROR(INDEX('Prospects'!$K$5:$K$504,MATCH(LARGE('Prospects'!$BT$5:$BT$504,2),'Prospects'!$BT$5:$BT$504,0)),"") | E34: =IFERROR(INDEX('Prospects'!$BC$5:$BC$504,MATCH(LARGE('Prospects'!$BT$5:$BT$504,2),'Prospects'!$BT$5:$BT$504,0)),"") | F34: =IFERROR(INDEX('Prospects'!$E$5:$E$504,MATCH(LARGE('Prospects'!$BT$5:$BT$504,2),'Prospects'!$BT$5:$BT$504,0)),"") | G34: =IFERROR(INDEX('Prospects'!$D$5:$D$504,MATCH(LARGE('Prospects'!$BT$5:$BT$504,2),'Prospects'!$BT$5:$BT$504,0)),"") | H34: =IFERROR(INDEX('Prospects'!$I$5:$I$504,MATCH(LARGE('Prospects'!$BT$5:$BT$504,2),'Prospects'!$BT$5:$BT$504,0)),"") | I34: =IFERROR(INDEX('Prospects'!$O$5:$O$504,MATCH(LARGE('Prospects'!$BT$5:$BT$504,2),'Prospects'!$BT$5:$BT$504,0)),"") | J34: =IFERROR(INDEX('Prospects'!$Z$5:$Z$504,MATCH(LARGE('Prospects'!$BT$5:$BT$504,2),'Prospects'!$BT$5:$BT$504,0)),"") | K34: =IFERROR(INDEX('Prospects'!$S$5:$S$504,MATCH(LARGE('Prospects'!$BT$5:$BT$504,2),'Prospects'!$BT$5:$BT$504,0)),"")
B35: =IFERROR(INDEX('Prospects'!$C$5:$C$504,MATCH(LARGE('Prospects'!$BT$5:$BT$504,3),'Prospects'!$BT$5:$BT$504,0)),"") | C35: =IFERROR(INDEX('Prospects'!$J$5:$J$504,MATCH(LARGE('Prospects'!$BT$5:$BT$504,3),'Prospects'!$BT$5:$BT$504,0)),"") | D35: =IFERROR(INDEX('Prospects'!$K$5:$K$504,MATCH(LARGE('Prospects'!$BT$5:$BT$504,3),'Prospects'!$BT$5:$BT$504,0)),"") | E35: =IFERROR(INDEX('Prospects'!$BC$5:$BC$504,MATCH(LARGE('Prospects'!$BT$5:$BT$504,3),'Prospects'!$BT$5:$BT$504,0)),"") | F35: =IFERROR(INDEX('Prospects'!$E$5:$E$504,MATCH(LARGE('Prospects'!$BT$5:$BT$504,3),'Prospects'!$BT$5:$BT$504,0)),"") | G35: =IFERROR(INDEX('Prospects'!$D$5:$D$504,MATCH(LARGE('Prospects'!$BT$5:$BT$504,3),'Prospects'!$BT$5:$BT$504,0)),"") | H35: =IFERROR(INDEX('Prospects'!$I$5:$I$504,MATCH(LARGE('Prospects'!$BT$5:$BT$504,3),'Prospects'!$BT$5:$BT$504,0)),"") | I35: =IFERROR(INDEX('Prospects'!$O$5:$O$504,MATCH(LARGE('Prospects'!$BT$5:$BT$504,3),'Prospects'!$BT$5:$BT$504,0)),"") | J35: =IFERROR(INDEX('Prospects'!$Z$5:$Z$504,MATCH(LARGE('Prospects'!$BT$5:$BT$504,3),'Prospects'!$BT$5:$BT$504,0)),"") | K35: =IFERROR(INDEX('Prospects'!$S$5:$S$504,MATCH(LARGE('Prospects'!$BT$5:$BT$504,3),'Prospects'!$BT$5:$BT$504,0)),"")
B36: =IFERROR(INDEX('Prospects'!$C$5:$C$504,MATCH(LARGE('Prospects'!$BT$5:$BT$504,4),'Prospects'!$BT$5:$BT$504,0)),"") | C36: =IFERROR(INDEX('Prospects'!$J$5:$J$504,MATCH(LARGE('Prospects'!$BT$5:$BT$504,4),'Prospects'!$BT$5:$BT$504,0)),"") | D36: =IFERROR(INDEX('Prospects'!$K$5:$K$504,MATCH(LARGE('Prospects'!$BT$5:$BT$504,4),'Prospects'!$BT$5:$BT$504,0)),"") | E36: =IFERROR(INDEX('Prospects'!$BC$5:$BC$504,MATCH(LARGE('Prospects'!$BT$5:$BT$504,4),'Prospects'!$BT$5:$BT$504,0)),"") | F36: =IFERROR(INDEX('Prospects'!$E$5:$E$504,MATCH(LARGE('Prospects'!$BT$5:$BT$504,4),'Prospects'!$BT$5:$BT$504,0)),"") | G36: =IFERROR(INDEX('Prospects'!$D$5:$D$504,MATCH(LARGE('Prospects'!$BT$5:$BT$504,4),'Prospects'!$BT$5:$BT$504,0)),"") | H36: =IFERROR(INDEX('Prospects'!$I$5:$I$504,MATCH(LARGE('Prospects'!$BT$5:$BT$504,4),'Prospects'!$BT$5:$BT$504,0)),"") | I36: =IFERROR(INDEX('Prospects'!$O$5:$O$504,MATCH(LARGE('Prospects'!$BT$5:$BT$504,4),'Prospects'!$BT$5:$BT$504,0)),"") | J36: =IFERROR(INDEX('Prospects'!$Z$5:$Z$504,MATCH(LARGE('Prospects'!$BT$5:$BT$504,4),'Prospects'!$BT$5:$BT$504,0)),"") | K36: =IFERROR(INDEX('Prospects'!$S$5:$S$504,MATCH(LARGE('Prospects'!$BT$5:$BT$504,4),'Prospects'!$BT$5:$BT$504,0)),"")
B37: =IFERROR(INDEX('Prospects'!$C$5:$C$504,MATCH(LARGE('Prospects'!$BT$5:$BT$504,5),'Prospects'!$BT$5:$BT$504,0)),"") | C37: =IFERROR(INDEX('Prospects'!$J$5:$J$504,MATCH(LARGE('Prospects'!$BT$5:$BT$504,5),'Prospects'!$BT$5:$BT$504,0)),"") | D37: =IFERROR(INDEX('Prospects'!$K$5:$K$504,MATCH(LARGE('Prospects'!$BT$5:$BT$504,5),'Prospects'!$BT$5:$BT$504,0)),"") | E37: =IFERROR(INDEX('Prospects'!$BC$5:$BC$504,MATCH(LARGE('Prospects'!$BT$5:$BT$504,5),'Prospects'!$BT$5:$BT$504,0)),"") | F37: =IFERROR(INDEX('Prospects'!$E$5:$E$504,MATCH(LARGE('Prospects'!$BT$5:$BT$504,5),'Prospects'!$BT$5:$BT$504,0)),"") | G37: =IFERROR(INDEX('Prospects'!$D$5:$D$504,MATCH(LARGE('Prospects'!$BT$5:$BT$504,5),'Prospects'!$BT$5:$BT$504,0)),"") | H37: =IFERROR(INDEX('Prospects'!$I$5:$I$504,MATCH(LARGE('Prospects'!$BT$5:$BT$504,5),'Prospects'!$BT$5:$BT$504,0)),"") | I37: =IFERROR(INDEX('Prospects'!$O$5:$O$504,MATCH(LARGE('Prospects'!$BT$5:$BT$504,5),'Prospects'!$BT$5:$BT$504,0)),"") | J37: =IFERROR(INDEX('Prospects'!$Z$5:$Z$504,MATCH(LARGE('Prospects'!$BT$5:$BT$504,5),'Prospects'!$BT$5:$BT$504,0)),"") | K37: =IFERROR(INDEX('Prospects'!$S$5:$S$504,MATCH(LARGE('Prospects'!$BT$5:$BT$504,5),'Prospects'!$BT$5:$BT$504,0)),"")
B38: =IFERROR(INDEX('Prospects'!$C$5:$C$504,MATCH(LARGE('Prospects'!$BT$5:$BT$504,6),'Prospects'!$BT$5:$BT$504,0)),"") | C38: =IFERROR(INDEX('Prospects'!$J$5:$J$504,MATCH(LARGE('Prospects'!$BT$5:$BT$504,6),'Prospects'!$BT$5:$BT$504,0)),"") | D38: =IFERROR(INDEX('Prospects'!$K$5:$K$504,MATCH(LARGE('Prospects'!$BT$5:$BT$504,6),'Prospects'!$BT$5:$BT$504,0)),"") | E38: =IFERROR(INDEX('Prospects'!$BC$5:$BC$504,MATCH(LARGE('Prospects'!$BT$5:$BT$504,6),'Prospects'!$BT$5:$BT$504,0)),"") | F38: =IFERROR(INDEX('Prospects'!$E$5:$E$504,MATCH(LARGE('Prospects'!$BT$5:$BT$504,6),'Prospects'!$BT$5:$BT$504,0)),"") | G38: =IFERROR(INDEX('Prospects'!$D$5:$D$504,MATCH(LARGE('Prospects'!$BT$5:$BT$504,6),'Prospects'!$BT$5:$BT$504,0)),"") | H38: =IFERROR(INDEX('Prospects'!$I$5:$I$504,MATCH(LARGE('Prospects'!$BT$5:$BT$504,6),'Prospects'!$BT$5:$BT$504,0)),"") | I38: =IFERROR(INDEX('Prospects'!$O$5:$O$504,MATCH(LARGE('Prospects'!$BT$5:$BT$504,6),'Prospects'!$BT$5:$BT$504,0)),"") | J38: =IFERROR(INDEX('Prospects'!$Z$5:$Z$504,MATCH(LARGE('Prospects'!$BT$5:$BT$504,6),'Prospects'!$BT$5:$BT$504,0)),"") | K38: =IFERROR(INDEX('Prospects'!$S$5:$S$504,MATCH(LARGE('Prospects'!$BT$5:$BT$504,6),'Prospects'!$BT$5:$BT$504,0)),"")
B39: =IFERROR(INDEX('Prospects'!$C$5:$C$504,MATCH(LARGE('Prospects'!$BT$5:$BT$504,7),'Prospects'!$BT$5:$BT$504,0)),"") | C39: =IFERROR(INDEX('Prospects'!$J$5:$J$504,MATCH(LARGE('Prospects'!$BT$5:$BT$504,7),'Prospects'!$BT$5:$BT$504,0)),"") | D39: =IFERROR(INDEX('Prospects'!$K$5:$K$504,MATCH(LARGE('Prospects'!$BT$5:$BT$504,7),'Prospects'!$BT$5:$BT$504,0)),"") | E39: =IFERROR(INDEX('Prospects'!$BC$5:$BC$504,MATCH(LARGE('Prospects'!$BT$5:$BT$504,7),'Prospects'!$BT$5:$BT$504,0)),"") | F39: =IFERROR(INDEX('Prospects'!$E$5:$E$504,MATCH(LARGE('Prospects'!$BT$5:$BT$504,7),'Prospects'!$BT$5:$BT$504,0)),"") | G39: =IFERROR(INDEX('Prospects'!$D$5:$D$504,MATCH(LARGE('Prospects'!$BT$5:$BT$504,7),'Prospects'!$BT$5:$BT$504,0)),"") | H39: =IFERROR(INDEX('Prospects'!$I$5:$I$504,MATCH(LARGE('Prospects'!$BT$5:$BT$504,7),'Prospects'!$BT$5:$BT$504,0)),"") | I39: =IFERROR(INDEX('Prospects'!$O$5:$O$504,MATCH(LARGE('Prospects'!$BT$5:$BT$504,7),'Prospects'!$BT$5:$BT$504,0)),"") | J39: =IFERROR(INDEX('Prospects'!$Z$5:$Z$504,MATCH(LARGE('Prospects'!$BT$5:$BT$504,7),'Prospects'!$BT$5:$BT$504,0)),"") | K39: =IFERROR(INDEX('Prospects'!$S$5:$S$504,MATCH(LARGE('Prospects'!$BT$5:$BT$504,7),'Prospects'!$BT$5:$BT$504,0)),"")
B40: =IFERROR(INDEX('Prospects'!$C$5:$C$504,MATCH(LARGE('Prospects'!$BT$5:$BT$504,8),'Prospects'!$BT$5:$BT$504,0)),"") | C40: =IFERROR(INDEX('Prospects'!$J$5:$J$504,MATCH(LARGE('Prospects'!$BT$5:$BT$504,8),'Prospects'!$BT$5:$BT$504,0)),"") | D40: =IFERROR(INDEX('Prospects'!$K$5:$K$504,MATCH(LARGE('Prospects'!$BT$5:$BT$504,8),'Prospects'!$BT$5:$BT$504,0)),"") | E40: =IFERROR(INDEX('Prospects'!$BC$5:$BC$504,MATCH(LARGE('Prospects'!$BT$5:$BT$504,8),'Prospects'!$BT$5:$BT$504,0)),"") | F40: =IFERROR(INDEX('Prospects'!$E$5:$E$504,MATCH(LARGE('Prospects'!$BT$5:$BT$504,8),'Prospects'!$BT$5:$BT$504,0)),"") | G40: =IFERROR(INDEX('Prospects'!$D$5:$D$504,MATCH(LARGE('Prospects'!$BT$5:$BT$504,8),'Prospects'!$BT$5:$BT$504,0)),"") | H40: =IFERROR(INDEX('Prospects'!$I$5:$I$504,MATCH(LARGE('Prospects'!$BT$5:$BT$504,8),'Prospects'!$BT$5:$BT$504,0)),"") | I40: =IFERROR(INDEX('Prospects'!$O$5:$O$504,MATCH(LARGE('Prospects'!$BT$5:$BT$504,8),'Prospects'!$BT$5:$BT$504,0)),"") | J40: =IFERROR(INDEX('Prospects'!$Z$5:$Z$504,MATCH(LARGE('Prospects'!$BT$5:$BT$504,8),'Prospects'!$BT$5:$BT$504,0)),"") | K40: =IFERROR(INDEX('Prospects'!$S$5:$S$504,MATCH(LARGE('Prospects'!$BT$5:$BT$504,8),'Prospects'!$BT$5:$BT$504,0)),"")
B41: =IFERROR(INDEX('Prospects'!$C$5:$C$504,MATCH(LARGE('Prospects'!$BT$5:$BT$504,9),'Prospects'!$BT$5:$BT$504,0)),"") | C41: =IFERROR(INDEX('Prospects'!$J$5:$J$504,MATCH(LARGE('Prospects'!$BT$5:$BT$504,9),'Prospects'!$BT$5:$BT$504,0)),"") | D41: =IFERROR(INDEX('Prospects'!$K$5:$K$504,MATCH(LARGE('Prospects'!$BT$5:$BT$504,9),'Prospects'!$BT$5:$BT$504,0)),"") | E41: =IFERROR(INDEX('Prospects'!$BC$5:$BC$504,MATCH(LARGE('Prospects'!$BT$5:$BT$504,9),'Prospects'!$BT$5:$BT$504,0)),"") | F41: =IFERROR(INDEX('Prospects'!$E$5:$E$504,MATCH(LARGE('Prospects'!$BT$5:$BT$504,9),'Prospects'!$BT$5:$BT$504,0)),"") | G41: =IFERROR(INDEX('Prospects'!$D$5:$D$504,MATCH(LARGE('Prospects'!$BT$5:$BT$504,9),'Prospects'!$BT$5:$BT$504,0)),"") | H41: =IFERROR(INDEX('Prospects'!$I$5:$I$504,MATCH(LARGE('Prospects'!$BT$5:$BT$504,9),'Prospects'!$BT$5:$BT$504,0)),"") | I41: =IFERROR(INDEX('Prospects'!$O$5:$O$504,MATCH(LARGE('Prospects'!$BT$5:$BT$504,9),'Prospects'!$BT$5:$BT$504,0)),"") | J41: =IFERROR(INDEX('Prospects'!$Z$5:$Z$504,MATCH(LARGE('Prospects'!$BT$5:$BT$504,9),'Prospects'!$BT$5:$BT$504,0)),"") | K41: =IFERROR(INDEX('Prospects'!$S$5:$S$504,MATCH(LARGE('Prospects'!$BT$5:$BT$504,9),'Prospects'!$BT$5:$BT$504,0)),"")
B42: =IFERROR(INDEX('Prospects'!$C$5:$C$504,MATCH(LARGE('Prospects'!$BT$5:$BT$504,10),'Prospects'!$BT$5:$BT$504,0)),"") | C42: =IFERROR(INDEX('Prospects'!$J$5:$J$504,MATCH(LARGE('Prospects'!$BT$5:$BT$504,10),'Prospects'!$BT$5:$BT$504,0)),"") | D42: =IFERROR(INDEX('Prospects'!$K$5:$K$504,MATCH(LARGE('Prospects'!$BT$5:$BT$504,10),'Prospects'!$BT$5:$BT$504,0)),"") | E42: =IFERROR(INDEX('Prospects'!$BC$5:$BC$504,MATCH(LARGE('Prospects'!$BT$5:$BT$504,10),'Prospects'!$BT$5:$BT$504,0)),"") | F42: =IFERROR(INDEX('Prospects'!$E$5:$E$504,MATCH(LARGE('Prospects'!$BT$5:$BT$504,10),'Prospects'!$BT$5:$BT$504,0)),"") | G42: =IFERROR(INDEX('Prospects'!$D$5:$D$504,MATCH(LARGE('Prospects'!$BT$5:$BT$504,10),'Prospects'!$BT$5:$BT$504,0)),"") | H42: =IFERROR(INDEX('Prospects'!$I$5:$I$504,MATCH(LARGE('Prospects'!$BT$5:$BT$504,10),'Prospects'!$BT$5:$BT$504,0)),"") | I42: =IFERROR(INDEX('Prospects'!$O$5:$O$504,MATCH(LARGE('Prospects'!$BT$5:$BT$504,10),'Prospects'!$BT$5:$BT$504,0)),"") | J42: =IFERROR(INDEX('Prospects'!$Z$5:$Z$504,MATCH(LARGE('Prospects'!$BT$5:$BT$504,10),'Prospects'!$BT$5:$BT$504,0)),"") | K42: =IFERROR(INDEX('Prospects'!$S$5:$S$504,MATCH(LARGE('Prospects'!$BT$5:$BT$504,10),'Prospects'!$BT$5:$BT$504,0)),"")
B44: 🟠 ALERTES PROSPECTS
...

Sheet Saisie
A1: =HYPERLINK("#'Ma journée'!A1","☀ Ma journée") | B1: ✎ SAISIE — le seul onglet à remplir
A2: Une ligne par action : appel, DM, relance, audit, RDV, proposition, signature, paiement… Nouveau prospect : tape son nom et remplis sa fiche (colonnes du milieu) sur cette première ligne. Ensuite, choisis-le dans la liste. Tout le reste du fichier se met à jour tout seul. Ajoute les lignes à la suite, dans l'ordre chronologique. Les lignes « EXEMPLE » sont à supprimer.
A3: ACTION (à chaque ligne) | R3: FICHE PROSPECT (1re ligne du prospect, puis seulement si ça change) | AN3: QUALIFICATION | AR3: AUTOMATIQUE (ne pas modifier)
A4: Date | B4: Heure | C4: Prospect (entreprise) | D4: Canal | E4: Action | F4: Résultat | G4: Montant (€) | H4: Durée (min) | I4: Prochaine action | J4: Date de relance (vide = auto) | K4: Heure de rappel | L4: Objection / motif de perte | M4: Modèle / accroche | N4: Note (audit /100, satisfaction /10) | O4: N° facture | P4: Remise (€) | Q4: Notes | R4: Secteur | S4: Ville | T4: Zone | U4: Nom du contact | V4: Fonction | W4: Téléphone | X4: WhatsApp (si différent) | Y4: Instagram | Z4: Site internet | AA4: Source | AB4: Recommandé par | AC4: Pub Insta active ? | AD4: Date de la pub | AE4: Budget pub | AF4: Présence Google | AG4: Note Google | AH4: Nb avis Google | AI4: Taille | AJ4: Concurrent en place | AK4: Personne au standard | AL4: Offre | AM4: Abonnement mensuel (€) | AN4: Budget OK ? | AO4: Décideur joint ? | AP4: Besoin confirmé ? | AQ4: Délai | AR4: Contrôle | AS4: N° ligne | AT4: Étape atteinte | AU4: Prospection ? | AV4: Réponse ? | AW4: Montant retenu | AX4: N° prospect | AY4: Heure (h) | AZ4: Jour (1 = lundi) | BA4: Canal du prospect | BB4: Rang fiche
A5: 46266 | E5: Dépense | G5: 49 | Q5: Abonnement Loom (EXEMPLE) | AR5: =IF(AND(C5="",E5=""),"",IF(A5="","⚠ Date manquante",IF(AND(C5="",E5<>"Dépense"),"⚠ Prospect manquant",IF(E5="","⚠ Action manquante",IF(AND(AU5=1,D5=""),"⚠ Canal manquant",IF(AND(W5<>"",COUNTIFS('Saisie'!$W$5:$W$2004,W5,'Saisie'!$C$5:$C$2004,"<>"&C5)>0),"⚠ Numéro déjà utilisé par un autre prospect",IF(AND(J5<>"",J5<A5),"⚠ Relance avant la date de l'action",IF(A5>TODAY(),"⚠ Date dans le futur","✓")))))))) | AS5: =IF(AND(A5="",C5="",E5=""),"",ROW()) | AT5: =IF(E5&F5="","",MAX(IFERROR(INDEX('Paramètres'!$J$6:$J$33,MATCH(E5,'Paramètres'!$I$6:$I$33,0)),0),IFERROR(INDEX('Paramètres'!$N$6:$N$17,MATCH(F5,'Paramètres'!$M$6:$M$17,0)),0))) | AU5: =IF(E5="","",IFERROR(IF(INDEX('Paramètres'!$K$6:$K$33,MATCH(E5,'Paramètres'!$I$6:$I$33,0))="Oui",1,0),0)) | AV5: =IF(F5="","",IFERROR(IF(INDEX('Paramètres'!$O$6:$O$17,MATCH(F5,'Paramètres'!$M$6:$M$17,0))="Oui",1,0),0)) | AW5: =IF(E5="","",IF(G5<>"",G5,IF(OR(E5="Proposition envoyée",E5="Signature"),MAX(0,N(IFERROR(INDEX('Paramètres'!$R$6:$R$15,MATCH(IF(AL5<>"",AL5,IFERROR(INDEX('Prospects'!$AN$5:$AN$504,MATCH(C5,'Prospects'!$C$5:$C$504,0)),"")),'Paramètres'!$Q$6:$Q$15,0)),0))-N(P5)),0))) | AX5: =IF(C5="","",IF(COUNTIF($C$5:C5,C5)=1,MAX($AX$4:AX4)+1,"")) | AY5: =IF(B5="","",HOUR(B5)) | AZ5: =IF(A5="","",MOD(A5-2,7)+1) | BA5: =IF(C5="","",IFERROR(INDEX('Prospects'!$N$5:$N$504,MATCH(C5,'Prospects'!$C$5:$C$504,0)),"")) | BB5: =IF(AND(C5<>"",C5='Fiche prospect'!$C$4),COUNTIF($C$5:C5,C5),"")
A6: 46275 | B6: 0.45833333 | C6: Studio Fit (EXEMPLE) | D6: Facebook | E6: Premier contact | F6: Pas intéressé | L6: J'ai déjà quelqu'un | M6: DM 2 - Audit gratuit | R6: Sport / Fitness | S6: Lyon | T6: Périphérie | U6: Léa Dubois | W6: 06 11 22 33 44 | Y6: @studiofit | Z6: studiofit.fr | AA6: Facebook | AC6: Non | AF6: Bonne | AI6: Moyenne | AR6: =IF(AND(C6="",E6=""),"",IF(A6="","⚠ Date manquante",IF(AND(C6="",E6<>"Dépense"),"⚠ Prospect manquant",IF(E6="","⚠ Action manquante",IF(AND(AU6=1,D6=""),"⚠ Canal manquant",IF(AND(W6<>"",COUNTIFS('Saisie'!$W$5:$W$2004,W6,'Saisie'!$C$5:$C$2004,"<>"&C6)>0),"⚠ Numéro déjà utilisé par un autre prospect",IF(AND(J6<>"",J6<A6),"⚠ Relance avant la date de l'action",IF(A6>TODAY(),"⚠ Date dans le futur","✓")))))))) | AS6: =IF(AND(A6="",C6="",E6=""),"",ROW()) | AT6: =IF(E6&F6="","",MAX(IFERROR(INDEX('Paramètres'!$J$6:$J$33,MATCH(E6,'Paramètres'!$I$6:$I$33,0)),0),IFERROR(INDEX('Paramètres'!$N$6:$N$17,MATCH(F6,'Paramètres'!$M$6:$M$17,0)),0))) | AU6: =IF(E6="","",IFERROR(IF(INDEX('Paramètres'!$K$6:$K$33,MATCH(E6,'Paramètres'!$I$6:$I$33,0))="Oui",1,0),0)) | AV6: =IF(F6="","",IFERROR(IF(INDEX('Paramètres'!$O$6:$O$17,MATCH(F6,'Paramètres'!$M$6:$M$17,0))="Oui",1,0),0)) | AW6: =IF(E6="","",IF(G6<>"",G6,IF(OR(E6="Proposition envoyée",E6="Signature"),MAX(0,N(IFERROR(INDEX('Paramètres'!$R$6:$R$15,MATCH(IF(AL6<>"",AL6,IFERROR(INDEX('Prospects'!$AN$5:$AN$504,MATCH(C6,'Prospects'!$C$5:$C$504,0)),"")),'Paramètres'!$Q$6:$Q$15,0)),0))-N(P6)),0))) | AX6: =IF(C6="","",IF(COUNTIF($C$5:C6,C6)=1,MAX($AX$4:AX5)+1,"")) | AY6: =IF(B6="","",HOUR(B6)) | AZ6: =IF(A6="","",MOD(A6-2,7)+1) | BA6: =IF(C6="","",IFERROR(INDEX('Prospects'!$N$5:$N$504,MATCH(C6,'Prospects'!$C$5:$C$504,0)),"")) | BB6: =IF(AND(C6<>"",C6='Fiche prospect'!$C$4),COUNTIF($C$5:C6,C6),"")
A7: 46277 | C7: Studio Fit (EXEMPLE) | E7: Perdu | L7: J'ai déjà quelqu'un | AR7: =IF(AND(C7="",E7=""),"",IF(A7="","⚠ Date manquante",IF(AND(C7="",E7<>"Dépense"),"⚠ Prospect manquant",IF(E7="","⚠ Action manquante",IF(AND(AU7=1,D7=""),"⚠ Canal manquant",IF(AND(W7<>"",COUNTIFS('Saisie'!$W$5:$W$2004,W7,'Saisie'!$C$5:$C$2004,"<>"&C7)>0),"⚠ Numéro déjà utilisé par un autre prospect",IF(AND(J7<>"",J7<A7),"⚠ Relance avant la date de l'action",IF(A7>TODAY(),"⚠ Date dans le futur","✓")))))))) | AS7: =IF(AND(A7="",C7="",E7=""),"",ROW()) | AT7: =IF(E7&F7="","",MAX(IFERROR(INDEX('Paramètres'!$J$6:$J$33,MATCH(E7,'Paramètres'!$I$6:$I$33,0)),0),IFERROR(INDEX('Paramètres'!$N$6:$N$17,MATCH(F7,'Paramètres'!$M$6:$M$17,0)),0))) | AU7: =IF(E7="","",IFERROR(IF(INDEX('Paramètres'!$K$6:$K$33,MATCH(E7,'Paramètres'!$I$6:$I$33,0))="Oui",1,0),0)) | AV7: =IF(F7="","",IFERROR(IF(INDEX('Paramètres'!$O$6:$O$17,MATCH(F7,'Paramètres'!$M$6:$M$17,0))="Oui",1,0),0)) | AW7: =IF(E7="","",IF(G7<>"",G7,IF(OR(E7="Proposition envoyée",E7="Signature"),MAX(0,N(IFERROR(INDEX('Paramètres'!$R$6:$R$15,MATCH(IF(AL7<>"",AL7,IFERROR(INDEX('Prospects'!$AN$5:$AN$504,MATCH(C7,'Prospects'!$C$5:$C$504,0)),"")),'Paramètres'!$Q$6:$Q$15,0)),0))-N(P7)),0))) | AX7: =IF(C7="","",IF(COUNTIF($C$5:C7,C7)=1,MAX($AX$4:AX6)+1,"")) | AY7: =IF(B7="","",HOUR(B7)) | AZ7: =IF(A7="","",MOD(A7-2,7)+1) | BA7: =IF(C7="","",IFERROR(INDEX('Prospects'!$N$5:$N$504,MATCH(C7,'Prospects'!$C$5:$C$504,0)),"")) | BB7: =IF(AND(C7<>"",C7='Fiche prospect'!$C$4),COUNTIF($C$5:C7,C7),"")
A8: 46280 | B8: 0.73611111 | C8: Pizzeria Da Marco (EXEMPLE) | D8: Appel | E8: Premier contact | F8: Messagerie - vocal laissé | H8: 1 | M8: Accroche A - Pub Insta | R8: Restaurant | S8: Lyon | T8: Centre-ville | U8: Marco Rossi | V8: Gérant | W8: 06 55 44 33 22 | Y8: @damarco | Z8: damarco.fr | AA8: Publicité Instagram | AC8: Oui | AD8: 46275 | AE8: Occasionnelle | AF8: Bonne | AG8: 4.6 | AH8: 210 | AI8: Petite | AR8: =IF(AND(C8="",E8=""),"",IF(A8="","⚠ Date manquante",IF(AND(C8="",E8<>"Dépense"),"⚠ Prospect manquant",IF(E8="","⚠ Action manquante",IF(AND(AU8=1,D8=""),"⚠ Canal manquant",IF(AND(W8<>"",COUNTIFS('Saisie'!$W$5:$W$2004,W8,'Saisie'!$C$5:$C$2004,"<>"&C8)>0),"⚠ Numéro déjà utilisé par un autre prospect",IF(AND(J8<>"",J8<A8),"⚠ Relance avant la date de l'action",IF(A8>TODAY(),"⚠ Date dans le futur","✓")))))))) | AS8: =IF(AND(A8="",C8="",E8=""),"",ROW()) | AT8: =IF(E8&F8="","",MAX(IFERROR(INDEX('Paramètres'!$J$6:$J$33,MATCH(E8,'Paramètres'!$I$6:$I$33,0)),0),IFERROR(INDEX('Paramètres'!$N$6:$N$17,MATCH(F8,'Paramètres'!$M$6:$M$17,0)),0))) | AU8: =IF(E8="","",IFERROR(IF(INDEX('Paramètres'!$K$6:$K$33,MATCH(E8,'Paramètres'!$I$6:$I$33,0))="Oui",1,0),0)) | AV8: =IF(F8="","",IFERROR(IF(INDEX('Paramètres'!$O$6:$O$17,MATCH(F8,'Paramètres'!$M$6:$M$17,0))="Oui",1,0),0)) | AW8: =IF(E8="","",IF(G8<>"",G8,IF(OR(E8="Proposition envoyée",E8="Signature"),MAX(0,N(IFERROR(INDEX('Paramètres'!$R$6:$R$15,MATCH(IF(AL8<>"",AL8,IFERROR(INDEX('Prospects'!$AN$5:$AN$504,MATCH(C8,'Prospects'!$C$5:$C$504,0)),"")),'Paramètres'!$Q$6:$Q$15,0)),0))-N(P8)),0))) | AX8: =IF(C8="","",IF(COUNTIF($C$5:C8,C8)=1,MAX($AX$4:AX7)+1,"")) | AY8: =IF(B8="","",HOUR(B8)) | AZ8: =IF(A8="","",MOD(A8-2,7)+1) | BA8: =IF(C8="","",IFERROR(INDEX('Prospects'!$N$5:$N$504,MATCH(C8,'Prospects'!$C$5:$C$504,0)),"")) | BB8: =IF(AND(C8<>"",C8='Fiche prospect'!$C$4),COUNTIF($C$5:C8,C8),"")
A9: 46281 | B9: 0.75694444 | C9: Pizzeria Da Marco (EXEMPLE) | D9: Appel | E9: Relance | F9: Intéressé | H9: 5 | I9: Rappeler pour fixer le RDV | J9: 46285 | K9: 0.45833333 | AN9: À voir | AO9: Oui | AP9: Oui | AR9: =IF(AND(C9="",E9=""),"",IF(A9="","⚠ Date manquante",IF(AND(C9="",E9<>"Dépense"),"⚠ Prospect manquant",IF(E9="","⚠ Action manquante",IF(AND(AU9=1,D9=""),"⚠ Canal manquant",IF(AND(W9<>"",COUNTIFS('Saisie'!$W$5:$W$2004,W9,'Saisie'!$C$5:$C$2004,"<>"&C9)>0),"⚠ Numéro déjà utilisé par un autre prospect",IF(AND(J9<>"",J9<A9),"⚠ Relance avant la date de l'action",IF(A9>TODAY(),"⚠ Date dans le futur","✓")))))))) | AS9: =IF(AND(A9="",C9="",E9=""),"",ROW()) | AT9: =IF(E9&F9="","",MAX(IFERROR(INDEX('Paramètres'!$J$6:$J$33,MATCH(E9,'Paramètres'!$I$6:$I$33,0)),0),IFERROR(INDEX('Paramètres'!$N$6:$N$17,MATCH(F9,'Paramètres'!$M$6:$M$17,0)),0))) | AU9: =IF(E9="","",IFERROR(IF(INDEX('Paramètres'!$K$6:$K$33,MATCH(E9,'Paramètres'!$I$6:$I$33,0))="Oui",1,0),0)) | AV9: =IF(F9="","",IFERROR(IF(INDEX('Paramètres'!$O$6:$O$17,MATCH(F9,'Paramètres'!$M$6:$M$17,0))="Oui",1,0),0)) | AW9: =IF(E9="","",IF(G9<>"",G9,IF(OR(E9="Proposition envoyée",E9="Signature"),MAX(0,N(IFERROR(INDEX('Paramètres'!$R$6:$R$15,MATCH(IF(AL9<>"",AL9,IFERROR(INDEX('Prospects'!$AN$5:$AN$504,MATCH(C9,'Prospects'!$C$5:$C$504,0)),"")),'Paramètres'!$Q$6:$Q$15,0)),0))-N(P9)),0))) | AX9: =IF(C9="","",IF(COUNTIF($C$5:C9,C9)=1,MAX($AX$4:AX8)+1,"")) | AY9: =IF(B9="","",HOUR(B9)) | AZ9: =IF(A9="","",MOD(A9-2,7)+1) | BA9: =IF(C9="","",IFERROR(INDEX('Prospects'!$N$5:$N$504,MATCH(C9,'Prospects'!$C$5:$C$504,0)),"")) | BB9: =IF(AND(C9<>"",C9='Fiche prospect'!$C$4),COUNTIF($C$5:C9,C9),"")
A10: 46286 | B10: 0.42708333 | C10: Institut Belle Peau (EXEMPLE) | D10: Appel | E10: Premier contact | F10: Intéressé | H10: 8 | I10: Envoyer audit + Loom | M10: Accroche A - Pub Insta | R10: Esthétique / Beauté | S10: Lyon | T10: Centre-ville | U10: Sarah Martin | V10: Gérante | W10: 06 12 34 56 78 | Y10: @bellepeau.lyon | Z10: bellepeau-lyon.fr | AA10: Publicité Instagram | AC10: Oui | AD10: 46283 | AE10: Régulière | AF10: Faible | AG10: 4.1 | AH10: 23 | AI10: Petite | AN10: Oui | AO10: Oui | AP10: Oui | AQ10: < 1 mois | AR10: =IF(AND(C10="",E10=""),"",IF(A10="","⚠ Date manquante",IF(AND(C10="",E10<>"Dépense"),"⚠ Prospect manquant",IF(E10="","⚠ Action manquante",IF(AND(AU10=1,D10=""),"⚠ Canal manquant",IF(AND(W10<>"",COUNTIFS('Saisie'!$W$5:$W$2004,W10,'Saisie'!$C$5:$C$2004,"<>"&C10)>0),"⚠ Numéro déjà utilisé par un autre prospect",IF(AND(J10<>"",J10<A10),"⚠ Relance avant la date de l'action",IF(A10>TODAY(),"⚠ Date dans le futur","✓")))))))) | AS10: =IF(AND(A10="",C10="",E10=""),"",ROW()) | AT10: =IF(E10&F10="","",MAX(IFERROR(INDEX('Paramètres'!$J$6:$J$33,MATCH(E10,'Paramètres'!$I$6:$I$33,0)),0),IFERROR(INDEX('Paramètres'!$N$6:$N$17,MATCH(F10,'Paramètres'!$M$6:$M$17,0)),0))) | AU10: =IF(E10="","",IFERROR(IF(INDEX('Paramètres'!$K$6:$K$33,MATCH(E10,'Paramètres'!$I$6:$I$33,0))="Oui",1,0),0)) | AV10: =IF(F10="","",IFERROR(IF(INDEX('Paramètres'!$O$6:$O$17,MATCH(F10,'Paramètres'!$M$6:$M$17,0))="Oui",1,0),0)) | AW10: =IF(E10="","",IF(G10<>"",G10,IF(OR(E10="Proposition envoyée",E10="Signature"),MAX(0,N(IFERROR(INDEX('Paramètres'!$R$6:$R$15,MATCH(IF(AL10<>"",AL10,IFERROR(INDEX('Prospects'!$AN$5:$AN$504,MATCH(C10,'Prospects'!$C$5:$C$504,0)),"")),'Paramètres'!$Q$6:$Q$15,0)),0))-N(P10)),0))) | AX10: =IF(C10="","",IF(COUNTIF($C$5:C10,C10)=1,MAX($AX$4:AX9)+1,"")) | AY10: =IF(B10="","",HOUR(B10)) | AZ10: =IF(A10="","",MOD(A10-2,7)+1) | BA10: =IF(C10="","",IFERROR(INDEX('Prospects'!$N$5:$N$504,MATCH(C10,'Prospects'!$C$5:$C$504,0)),"")) | BB10: =IF(AND(C10<>"",C10='Fiche prospect'!$C$4),COUNTIF($C$5:C10,C10),"")
A11: 46287 | C11: Institut Belle Peau (EXEMPLE) | E11: Audit réalisé | H11: 45 | N11: 38 | AR11: =IF(AND(C11="",E11=""),"",IF(A11="","⚠ Date manquante",IF(AND(C11="",E11<>"Dépense"),"⚠ Prospect manquant",IF(E11="","⚠ Action manquante",IF(AND(AU11=1,D11=""),"⚠ Canal manquant",IF(AND(W11<>"",COUNTIFS('Saisie'!$W$5:$W$2004,W11,'Saisie'!$C$5:$C$2004,"<>"&C11)>0),"⚠ Numéro déjà utilisé par un autre prospect",IF(AND(J11<>"",J11<A11),"⚠ Relance avant la date de l'action",IF(A11>TODAY(),"⚠ Date dans le futur","✓")))))))) | AS11: =IF(AND(A11="",C11="",E11=""),"",ROW()) | AT11: =IF(E11&F11="","",MAX(IFERROR(INDEX('Paramètres'!$J$6:$J$33,MATCH(E11,'Paramètres'!$I$6:$I$33,0)),0),IFERROR(INDEX('Paramètres'!$N$6:$N$17,MATCH(F11,'Paramètres'!$M$6:$M$17,0)),0))) | AU11: =IF(E11="","",IFERROR(IF(INDEX('Paramètres'!$K$6:$K$33,MATCH(E11,'Paramètres'!$I$6:$I$33,0))="Oui",1,0),0)) | AV11: =IF(F11="","",IFERROR(IF(INDEX('Paramètres'!$O$6:$O$17,MATCH(F11,'Paramètres'!$M$6:$M$17,0))="Oui",1,0),0)) | AW11: =IF(E11="","",IF(G11<>"",G11,IF(OR(E11="Proposition envoyée",E11="Signature"),MAX(0,N(IFERROR(INDEX('Paramètres'!$R$6:$R$15,MATCH(IF(AL11<>"",AL11,IFERROR(INDEX('Prospects'!$AN$5:$AN$504,MATCH(C11,'Prospects'!$C$5:$C$504,0)),"")),'Paramètres'!$Q$6:$Q$15,0)),0))-N(P11)),0))) | AX11: =IF(C11="","",IF(COUNTIF($C$5:C11,C11)=1,MAX($AX$4:AX10)+1,"")) | AY11: =IF(B11="","",HOUR(B11)) | AZ11: =IF(A11="","",MOD(A11-2,7)+1) | BA11: =IF(C11="","",IFERROR(INDEX('Prospects'!$N$5:$N$504,MATCH(C11,'Prospects'!$C$5:$C$504,0)),"")) | BB11: =IF(AND(C11<>"",C11='Fiche prospect'!$C$4),COUNTIF($C$5:C11,C11),"")
A12: 46287 | B12: 0.45833333 | C12: Garage Auto Rapide (EXEMPLE) | D12: DM | E12: Premier contact | F12: Pas de réponse | M12: DM 1 - Compliment + question | R12: Automobile | S12: Villeurbanne | T12: Périphérie | U12: Karim Benali | V12: Dirigeant | W12: 07 98 76 54 32 | Y12: @autorapide69 | AA12: Profil Instagram | AC12: Non | AF12: Absente | AI12: Moyenne | AR12: =IF(AND(C12="",E12=""),"",IF(A12="","⚠ Date manquante",IF(AND(C12="",E12<>"Dépense"),"⚠ Prospect manquant",IF(E12="","⚠ Action manquante",IF(AND(AU12=1,D12=""),"⚠ Canal manquant",IF(AND(W12<>"",COUNTIFS('Saisie'!$W$5:$W$2004,W12,'Saisie'!$C$5:$C$2004,"<>"&C12)>0),"⚠ Numéro déjà utilisé par un autre prospect",IF(AND(J12<>"",J12<A12),"⚠ Relance avant la date de l'action",IF(A12>TODAY(),"⚠ Date dans le futur","✓")))))))) | AS12: =IF(AND(A12="",C12="",E12=""),"",ROW()) | AT12: =IF(E12&F12="","",MAX(IFERROR(INDEX('Paramètres'!$J$6:$J$33,MATCH(E12,'Paramètres'!$I$6:$I$33,0)),0),IFERROR(INDEX('Paramètres'!$N$6:$N$17,MATCH(F12,'Paramètres'!$M$6:$M$17,0)),0))) | AU12: =IF(E12="","",IFERROR(IF(INDEX('Paramètres'!$K$6:$K$33,MATCH(E12,'Paramètres'!$I$6:$I$33,0))="Oui",1,0),0)) | AV12: =IF(F12="","",IFERROR(IF(INDEX('Paramètres'!$O$6:$O$17,MATCH(F12,'Paramètres'!$M$6:$M$17,0))="Oui",1,0),0)) | AW12: =IF(E12="","",IF(G12<>"",G12,IF(OR(E12="Proposition envoyée",E12="Signature"),MAX(0,N(IFERROR(INDEX('Paramètres'!$R$6:$R$15,MATCH(IF(AL12<>"",AL12,IFERROR(INDEX('Prospects'!$AN$5:$AN$504,MATCH(C12,'Prospects'!$C$5:$C$504,0)),"")),'Paramètres'!$Q$6:$Q$15,0)),0))-N(P12)),0))) | AX12: =IF(C12="","",IF(COUNTIF($C$5:C12,C12)=1,MAX($AX$4:AX11)+1,"")) | AY12: =IF(B12="","",HOUR(B12)) | AZ12: =IF(A12="","",MOD(A12-2,7)+1) | BA12: =IF(C12="","",IFERROR(INDEX('Prospects'!$N$5:$N$504,MATCH(C12,'Prospects'!$C$5:$C$504,0)),"")) | BB12: =IF(AND(C12<>"",C12='Fiche prospect'!$C$4),COUNTIF($C$5:C12,C12),"")
A13: 46287 | C13: Institut Belle Peau (EXEMPLE) | D13: WhatsApp | E13: Loom envoyé | F13: Loom vu | AR13: =IF(AND(C13="",E13=""),"",IF(A13="","⚠ Date manquante",IF(AND(C13="",E13<>"Dépense"),"⚠ Prospect manquant",IF(E13="","⚠ Action manquante",IF(AND(AU13=1,D13=""),"⚠ Canal manquant",IF(AND(W13<>"",COUNTIFS('Saisie'!$W$5:$W$2004,W13,'Saisie'!$C$5:$C$2004,"<>"&C13)>0),"⚠ Numéro déjà utilisé par un autre prospect",IF(AND(J13<>"",J13<A13),"⚠ Relance avant la date de l'action",IF(A13>TODAY(),"⚠ Date dans le futur","✓")))))))) | AS13: =IF(AND(A13="",C13="",E13=""),"",ROW()) | AT13: =IF(E13&F13="","",MAX(IFERROR(INDEX('Paramètres'!$J$6:$J$33,MATCH(E13,'Paramètres'!$I$6:$I$33,0)),0),IFERROR(INDEX('Paramètres'!$N$6:$N$17,MATCH(F13,'Paramètres'!$M$6:$M$17,0)),0))) | AU13: =IF(E13="","",IFERROR(IF(INDEX('Paramètres'!$K$6:$K$33,MATCH(E13,'Paramètres'!$I$6:$I$33,0))="Oui",1,0),0)) | AV13: =IF(F13="","",IFERROR(IF(INDEX('Paramètres'!$O$6:$O$17,MATCH(F13,'Paramètres'!$M$6:$M$17,0))="Oui",1,0),0)) | AW13: =IF(E13="","",IF(G13<>"",G13,IF(OR(E13="Proposition envoyée",E13="Signature"),MAX(0,N(IFERROR(INDEX('Paramètres'!$R$6:$R$15,MATCH(IF(AL13<>"",AL13,IFERROR(INDEX('Prospects'!$AN$5:$AN$504,MATCH(C13,'Prospects'!$C$5:$C$504,0)),"")),'Paramètres'!$Q$6:$Q$15,0)),0))-N(P13)),0))) | AX13: =IF(C13="","",IF(COUNTIF($C$5:C13,C13)=1,MAX($AX$4:AX12)+1,"")) | AY13: =IF(B13="","",HOUR(B13)) | AZ13: =IF(A13="","",MOD(A13-2,7)+1) | BA13: =IF(C13="","",IFERROR(INDEX('Prospects'!$N$5:$N$504,MATCH(C13,'Prospects'!$C$5:$C$504,0)),"")) | BB13: =IF(AND(C13<>"",C13='Fiche prospect'!$C$4),COUNTIF($C$5:C13,C13),"")
A14: 46288 | B14: 0.60416667 | C14: Institut Belle Peau (EXEMPLE) | D14: Appel | E14: Échange / suivi | F14: RDV pris | H14: 6 | AR14: =IF(AND(C14="",E14=""),"",IF(A14="","⚠ Date manquante",IF(AND(C14="",E14<>"Dépense"),"⚠ Prospect manquant",IF(E14="","⚠ Action manquante",IF(AND(AU14=1,D14=""),"⚠ Canal manquant",IF(AND(W14<>"",COUNTIFS('Saisie'!$W$5:$W$2004,W14,'Saisie'!$C$5:$C$2004,"<>"&C14)>0),"⚠ Numéro déjà utilisé par un autre prospect",IF(AND(J14<>"",J14<A14),"⚠ Relance avant la date de l'action",IF(A14>TODAY(),"⚠ Date dans le futur","✓")))))))) | AS14: =IF(AND(A14="",C14="",E14=""),"",ROW()) | AT14: =IF(E14&F14="","",MAX(IFERROR(INDEX('Paramètres'!$J$6:$J$33,MATCH(E14,'Paramètres'!$I$6:$I$33,0)),0),IFERROR(INDEX('Paramètres'!$N$6:$N$17,MATCH(F14,'Paramètres'!$M$6:$M$17,0)),0))) | AU14: =IF(E14="","",IFERROR(IF(INDEX('Paramètres'!$K$6:$K$33,MATCH(E14,'Paramètres'!$I$6:$I$33,0))="Oui",1,0),0)) | AV14: =IF(F14="","",IFERROR(IF(INDEX('Paramètres'!$O$6:$O$17,MATCH(F14,'Paramètres'!$M$6:$M$17,0))="Oui",1,0),0)) | AW14: =IF(E14="","",IF(G14<>"",G14,IF(OR(E14="Proposition envoyée",E14="Signature"),MAX(0,N(IFERROR(INDEX('Paramètres'!$R$6:$R$15,MATCH(IF(AL14<>"",AL14,IFERROR(INDEX('Prospects'!$AN$5:$AN$504,MATCH(C14,'Prospects'!$C$5:$C$504,0)),"")),'Paramètres'!$Q$6:$Q$15,0)),0))-N(P14)),0))) | AX14: =IF(C14="","",IF(COUNTIF($C$5:C14,C14)=1,MAX($AX$4:AX13)+1,"")) | AY14: =IF(B14="","",HOUR(B14)) | AZ14: =IF(A14="","",MOD(A14-2,7)+1) | BA14: =IF(C14="","",IFERROR(INDEX('Prospects'!$N$5:$N$504,MATCH(C14,'Prospects'!$C$5:$C$504,0)),"")) | BB14: =IF(AND(C14<>"",C14='Fiche prospect'!$C$4),COUNTIF($C$5:C14,C14),"")
A15: 46289 | B15: 0.39583333 | C15: Garage Auto Rapide (EXEMPLE) | D15: DM | E15: Relance | F15: Pas de réponse | M15: DM 2 - Audit gratuit | AR15: =IF(AND(C15="",E15=""),"",IF(A15="","⚠ Date manquante",IF(AND(C15="",E15<>"Dépense"),"⚠ Prospect manquant",IF(E15="","⚠ Action manquante",IF(AND(AU15=1,D15=""),"⚠ Canal manquant",IF(AND(W15<>"",COUNTIFS('Saisie'!$W$5:$W$2004,W15,'Saisie'!$C$5:$C$2004,"<>"&C15)>0),"⚠ Numéro déjà utilisé par un autre prospect",IF(AND(J15<>"",J15<A15),"⚠ Relance avant la date de l'action",IF(A15>TODAY(),"⚠ Date dans le futur","✓")))))))) | AS15: =IF(AND(A15="",C15="",E15=""),"",ROW()) | AT15: =IF(E15&F15="","",MAX(IFERROR(INDEX('Paramètres'!$J$6:$J$33,MATCH(E15,'Paramètres'!$I$6:$I$33,0)),0),IFERROR(INDEX('Paramètres'!$N$6:$N$17,MATCH(F15,'Paramètres'!$M$6:$M$17,0)),0))) | AU15: =IF(E15="","",IFERROR(IF(INDEX('Paramètres'!$K$6:$K$33,MATCH(E15,'Paramètres'!$I$6:$I$33,0))="Oui",1,0),0)) | AV15: =IF(F15="","",IFERROR(IF(INDEX('Paramètres'!$O$6:$O$17,MATCH(F15,'Paramètres'!$M$6:$M$17,0))="Oui",1,0),0)) | AW15: =IF(E15="","",IF(G15<>"",G15,IF(OR(E15="Proposition envoyée",E15="Signature"),MAX(0,N(IFERROR(INDEX('Paramètres'!$R$6:$R$15,MATCH(IF(AL15<>"",AL15,IFERROR(INDEX('Prospects'!$AN$5:$AN$504,MATCH(C15,'Prospects'!$C$5:$C$504,0)),"")),'Paramètres'!$Q$6:$Q$15,0)),0))-N(P15)),0))) | AX15: =IF(C15="","",IF(COUNTIF($C$5:C15,C15)=1,MAX($AX$4:AX14)+1,"")) | AY15: =IF(B15="","",HOUR(B15)) | AZ15: =IF(A15="","",MOD(A15-2,7)+1) | BA15: =IF(C15="","",IFERROR(INDEX('Prospects'!$N$5:$N$504,MATCH(C15,'Prospects'!$C$5:$C$504,0)),"")) | BB15: =IF(AND(C15<>"",C15='Fiche prospect'!$C$4),COUNTIF($C$5:C15,C15),"")
A16: 46289 | C16: Institut Belle Peau (EXEMPLE) | E16: RDV | F16: Intéressé | H16: 40 | I16: Envoyer la proposition | AR16: =IF(AND(C16="",E16=""),"",IF(A16="","⚠ Date manquante",IF(AND(C16="",E16<>"Dépense"),"⚠ Prospect manquant",IF(E16="","⚠ Action manquante",IF(AND(AU16=1,D16=""),"⚠ Canal manquant",IF(AND(W16<>"",COUNTIFS('Saisie'!$W$5:$W$2004,W16,'Saisie'!$C$5:$C$2004,"<>"&C16)>0),"⚠ Numéro déjà utilisé par un autre prospect",IF(AND(J16<>"",J16<A16),"⚠ Relance avant la date de l'action",IF(A16>TODAY(),"⚠ Date dans le futur","✓")))))))) | AS16: =IF(AND(A16="",C16="",E16=""),"",ROW()) | AT16: =IF(E16&F16="","",MAX(IFERROR(INDEX('Paramètres'!$J$6:$J$33,MATCH(E16,'Paramètres'!$I$6:$I$33,0)),0),IFERROR(INDEX('Paramètres'!$N$6:$N$17,MATCH(F16,'Paramètres'!$M$6:$M$17,0)),0))) | AU16: =IF(E16="","",IFERROR(IF(INDEX('Paramètres'!$K$6:$K$33,MATCH(E16,'Paramètres'!$I$6:$I$33,0))="Oui",1,0),0)) | AV16: =IF(F16="","",IFERROR(IF(INDEX('Paramètres'!$O$6:$O$17,MATCH(F16,'Paramètres'!$M$6:$M$17,0))="Oui",1,0),0)) | AW16: =IF(E16="","",IF(G16<>"",G16,IF(OR(E16="Proposition envoyée",E16="Signature"),MAX(0,N(IFERROR(INDEX('Paramètres'!$R$6:$R$15,MATCH(IF(AL16<>"",AL16,IFERROR(INDEX('Prospects'!$AN$5:$AN$504,MATCH(C16,'Prospects'!$C$5:$C$504,0)),"")),'Paramètres'!$Q$6:$Q$15,0)),0))-N(P16)),0))) | AX16: =IF(C16="","",IF(COUNTIF($C$5:C16,C16)=1,MAX($AX$4:AX15)+1,"")) | AY16: =IF(B16="","",HOUR(B16)) | AZ16: =IF(A16="","",MOD(A16-2,7)+1) | BA16: =IF(C16="","",IFERROR(INDEX('Prospects'!$N$5:$N$504,MATCH(C16,'Prospects'!$C$5:$C$504,0)),"")) | BB16: =IF(AND(C16<>"",C16='Fiche prospect'!$C$4),COUNTIF($C$5:C16,C16),"")
A17: 46289 | C17: Institut Belle Peau (EXEMPLE) | E17: Proposition envoyée | AL17: Site + réservation | AM17: 90 | AR17: =IF(AND(C17="",E17=""),"",IF(A17="","⚠ Date manquante",IF(AND(C17="",E17<>"Dépense"),"⚠ Prospect manquant",IF(E17="","⚠ Action manquante",IF(AND(AU17=1,D17=""),"⚠ Canal manquant",IF(AND(W17<>"",COUNTIFS('Saisie'!$W$5:$W$2004,W17,'Saisie'!$C$5:$C$2004,"<>"&C17)>0),"⚠ Numéro déjà utilisé par un autre prospect",IF(AND(J17<>"",J17<A17),"⚠ Relance avant la date de l'action",IF(A17>TODAY(),"⚠ Date dans le futur","✓")))))))) | AS17: =IF(AND(A17="",C17="",E17=""),"",ROW()) | AT17: =IF(E17&F17="","",MAX(IFERROR(INDEX('Paramètres'!$J$6:$J$33,MATCH(E17,'Paramètres'!$I$6:$I$33,0)),0),IFERROR(INDEX('Paramètres'!$N$6:$N$17,MATCH(F17,'Paramètres'!$M$6:$M$17,0)),0))) | AU17: =IF(E17="","",IFERROR(IF(INDEX('Paramètres'!$K$6:$K$33,MATCH(E17,'Paramètres'!$I$6:$I$33,0))="Oui",1,0),0)) | AV17: =IF(F17="","",IFERROR(IF(INDEX('Paramètres'!$O$6:$O$17,MATCH(F17,'Paramètres'!$M$6:$M$17,0))="Oui",1,0),0)) | AW17: =IF(E17="","",IF(G17<>"",G17,IF(OR(E17="Proposition envoyée",E17="Signature"),MAX(0,N(IFERROR(INDEX('Paramètres'!$R$6:$R$15,MATCH(IF(AL17<>"",AL17,IFERROR(INDEX('Prospects'!$AN$5:$AN$504,MATCH(C17,'Prospects'!$C$5:$C$504,0)),"")),'Paramètres'!$Q$6:$Q$15,0)),0))-N(P17)),0))) | AX17: =IF(C17="","",IF(COUNTIF($C$5:C17,C17)=1,MAX($AX$4:AX16)+1,"")) | AY17: =IF(B17="","",HOUR(B17)) | AZ17: =IF(A17="","",MOD(A17-2,7)+1) | BA17: =IF(C17="","",IFERROR(INDEX('Prospects'!$N$5:$N$504,MATCH(C17,'Prospects'!$C$5:$C$504,0)),"")) | BB17: =IF(AND(C17<>"",C17='Fiche prospect'!$C$4),COUNTIF($C$5:C17,C17),"")
A18: 46290 | C18: Institut Belle Peau (EXEMPLE) | E18: Signature | AR18: =IF(AND(C18="",E18=""),"",IF(A18="","⚠ Date manquante",IF(AND(C18="",E18<>"Dépense"),"⚠ Prospect manquant",IF(E18="","⚠ Action manquante",IF(AND(AU18=1,D18=""),"⚠ Canal manquant",IF(AND(W18<>"",COUNTIFS('Saisie'!$W$5:$W$2004,W18,'Saisie'!$C$5:$C$2004,"<>"&C18)>0),"⚠ Numéro déjà utilisé par un autre prospect",IF(AND(J18<>"",J18<A18),"⚠ Relance avant la date de l'action",IF(A18>TODAY(),"⚠ Date dans le futur","✓")))))))) | AS18: =IF(AND(A18="",C18="",E18=""),"",ROW()) | AT18: =IF(E18&F18="","",MAX(IFERROR(INDEX('Paramètres'!$J$6:$J$33,MATCH(E18,'Paramètres'!$I$6:$I$33,0)),0),IFERROR(INDEX('Paramètres'!$N$6:$N$17,MATCH(F18,'Paramètres'!$M$6:$M$17,0)),0))) | AU18: =IF(E18="","",IFERROR(IF(INDEX('Paramètres'!$K$6:$K$33,MATCH(E18,'Paramètres'!$I$6:$I$33,0))="Oui",1,0),0)) | AV18: =IF(F18="","",IFERROR(IF(INDEX('Paramètres'!$O$6:$O$17,MATCH(F18,'Paramètres'!$M$6:$M$17,0))="Oui",1,0),0)) | AW18: =IF(E18="","",IF(G18<>"",G18,IF(OR(E18="Proposition envoyée",E18="Signature"),MAX(0,N(IFERROR(INDEX('Paramètres'!$R$6:$R$15,MATCH(IF(AL18<>"",AL18,IFERROR(INDEX('Prospects'!$AN$5:$AN$504,MATCH(C18,'Prospects'!$C$5:$C$504,0)),"")),'Paramètres'!$Q$6:$Q$15,0)),0))-N(P18)),0))) | AX18: =IF(C18="","",IF(COUNTIF($C$5:C18,C18)=1,MAX($AX$4:AX17)+1,"")) | AY18: =IF(B18="","",HOUR(B18)) | AZ18: =IF(A18="","",MOD(A18-2,7)+1) | BA18: =IF(C18="","",IFERROR(INDEX('Prospects'!$N$5:$N$504,MATCH(C18,'Prospects'!$C$5:$C$504,0)),"")) | BB18: =IF(AND(C18<>"",C18='Fiche prospect'!$C$4),COUNTIF($C$5:C18,C18),"")
A19: 46290 | C19: Institut Belle Peau (EXEMPLE) | E19: Paiement reçu | G19: 900 | O19: F-2026-001 | Q19: Acompte 50 % | AR19: =IF(AND(C19="",E19=""),"",IF(A19="","⚠ Date manquante",IF(AND(C19="",E19<>"Dépense"),"⚠ Prospect manquant",IF(E19="","⚠ Action manquante",IF(AND(AU19=1,D19=""),"⚠ Canal manquant",IF(AND(W19<>"",COUNTIFS('Saisie'!$W$5:$W$2004,W19,'Saisie'!$C$5:$C$2004,"<>"&C19)>0),"⚠ Numéro déjà utilisé par un autre prospect",IF(AND(J19<>"",J19<A19),"⚠ Relance avant la date de l'action",IF(A19>TODAY(),"⚠ Date dans le futur","✓")))))))) | AS19: =IF(AND(A19="",C19="",E19=""),"",ROW()) | AT19: =IF(E19&F19="","",MAX(IFERROR(INDEX('Paramètres'!$J$6:$J$33,MATCH(E19,'Paramètres'!$I$6:$I$33,0)),0),IFERROR(INDEX('Paramètres'!$N$6:$N$17,MATCH(F19,'Paramètres'!$M$6:$M$17,0)),0))) | AU19: =IF(E19="","",IFERROR(IF(INDEX('Paramètres'!$K$6:$K$33,MATCH(E19,'Paramètres'!$I$6:$I$33,0))="Oui",1,0),0)) | AV19: =IF(F19="","",IFERROR(IF(INDEX('Paramètres'!$O$6:$O$17,MATCH(F19,'Paramètres'!$M$6:$M$17,0))="Oui",1,0),0)) | AW19: =IF(E19="","",IF(G19<>"",G19,IF(OR(E19="Proposition envoyée",E19="Signature"),MAX(0,N(IFERROR(INDEX('Paramètres'!$R$6:$R$15,MATCH(IF(AL19<>"",AL19,IFERROR(INDEX('Prospects'!$AN$5:$AN$504,MATCH(C19,'Prospects'!$C$5:$C$504,0)),"")),'Paramètres'!$Q$6:$Q$15,0)),0))-N(P19)),0))) | AX19: =IF(C19="","",IF(COUNTIF($C$5:C19,C19)=1,MAX($AX$4:AX18)+1,"")) | AY19: =IF(B19="","",HOUR(B19)) | AZ19: =IF(A19="","",MOD(A19-2,7)+1) | BA19: =IF(C19="","",IFERROR(INDEX('Prospects'!$N$5:$N$504,MATCH(C19,'Prospects'!$C$5:$C$504,0)),"")) | BB19: =IF(AND(C19<>"",C19='Fiche prospect'!$C$4),COUNTIF($C$5:C19,C19),"")
A20: 46290 | C20: Salon Coiff'Style (EXEMPLE) | D20: Appel | E20: Ajout prospect | R20: Coiffure | S20: Lyon | T20: Centre-ville | U20: Julie Petit | W20: 06 77 88 99 00 | Y20: @coiffstyle | AA20: Recommandation | AB20: Institut Belle Peau (EXEMPLE) | AC20: Oui | AD20: 46289 | AE20: Régulière | AF20: Absente | AI20: Petite | AR20: =IF(AND(C20="",E20=""),"",IF(A20="","⚠ Date manquante",IF(AND(C20="",E20<>"Dépense"),"⚠ Prospect manquant",IF(E20="","⚠ Action manquante",IF(AND(AU20=1,D20=""),"⚠ Canal manquant",IF(AND(W20<>"",COUNTIFS('Saisie'!$W$5:$W$2004,W20,'Saisie'!$C$5:$C$2004,"<>"&C20)>0),"⚠ Numéro déjà utilisé par un autre prospect",IF(AND(J20<>"",J20<A20),"⚠ Relance avant la date de l'action",IF(A20>TODAY(),"⚠ Date dans le futur","✓")))))))) | AS20: =IF(AND(A20="",C20="",E20=""),"",ROW()) | AT20: =IF(E20&F20="","",MAX(IFERROR(INDEX('Paramètres'!$J$6:$J$33,MATCH(E20,'Paramètres'!$I$6:$I$33,0)),0),IFERROR(INDEX('Paramètres'!$N$6:$N$17,MATCH(F20,'Paramètres'!$M$6:$M$17,0)),0))) | AU20: =IF(E20="","",IFERROR(IF(INDEX('Paramètres'!$K$6:$K$33,MATCH(E20,'Paramètres'!$I$6:$I$33,0))="Oui",1,0),0)) | AV20: =IF(F20="","",IFERROR(IF(INDEX('Paramètres'!$O$6:$O$17,MATCH(F20,'Paramètres'!$M$6:$M$17,0))="Oui",1,0),0)) | AW20: =IF(E20="","",IF(G20<>"",G20,IF(OR(E20="Proposition envoyée",E20="Signature"),MAX(0,N(IFERROR(INDEX('Paramètres'!$R$6:$R$15,MATCH(IF(AL20<>"",AL20,IFERROR(INDEX('Prospects'!$AN$5:$AN$504,MATCH(C20,'Prospects'!$C$5:$C$504,0)),"")),'Paramètres'!$Q$6:$Q$15,0)),0))-N(P20)),0))) | AX20: =IF(C20="","",IF(COUNTIF($C$5:C20,C20)=1,MAX($AX$4:AX19)+1,"")) | AY20: =IF(B20="","",HOUR(B20)) | AZ20: =IF(A20="","",MOD(A20-2,7)+1) | BA20: =IF(C20="","",IFERROR(INDEX('Prospects'!$N$5:$N$504,MATCH(C20,'Prospects'!$C$5:$C$504,0)),"")) | BB20: =IF(AND(C20<>"",C20='Fiche prospect'!$C$4),COUNTIF($C$5:C20,C20),"")
